
INFO:root:<QuerySet [<Deal: Deal object>, <Deal: Deal object>]>
INFO:root:[(<Tattoo: Tattoo object>, <User: ivdpopovich>, <User: emily>), (<Tattoo: Tattoo object>, <User: ivdpopovich>, <User: emily>)]
INFO:root:Darova
INFO:root:[]
ERROR:django.request:Internal Server Error: /deals/
Traceback (most recent call last):
  File "/home/jops/university/refactoring/tattoo/vtattoo/vtattooenv/lib/python3.5/site-packages/django/core/handlers/exception.py", line 41, in inner
    response = get_response(request)
  File "/home/jops/university/refactoring/tattoo/vtattoo/vtattooenv/lib/python3.5/site-packages/django/core/handlers/base.py", line 187, in _get_response
    response = self.process_exception_by_middleware(e, request)
  File "/home/jops/university/refactoring/tattoo/vtattoo/vtattooenv/lib/python3.5/site-packages/django/core/handlers/base.py", line 185, in _get_response
    response = wrapped_callback(request, *callback_args, **callback_kwargs)
  File "/home/jops/university/refactoring/tattoo/vtattoo/vtattooenv/lib/python3.5/site-packages/django/views/decorators/csrf.py", line 58, in wrapped_view
    return view_func(*args, **kwargs)
  File "/home/jops/university/refactoring/tattoo/vtattoo/vtattooenv/lib/python3.5/site-packages/django/views/generic/base.py", line 68, in view
    return self.dispatch(request, *args, **kwargs)
  File "/home/jops/university/refactoring/tattoo/vtattoo/vtattooenv/lib/python3.5/site-packages/rest_framework/views.py", line 477, in dispatch
    response = self.handle_exception(exc)
  File "/home/jops/university/refactoring/tattoo/vtattoo/vtattooenv/lib/python3.5/site-packages/rest_framework/views.py", line 437, in handle_exception
    self.raise_uncaught_exception(exc)
  File "/home/jops/university/refactoring/tattoo/vtattoo/vtattooenv/lib/python3.5/site-packages/rest_framework/views.py", line 448, in raise_uncaught_exception
    raise exc
  File "/home/jops/university/refactoring/tattoo/vtattoo/vtattooenv/lib/python3.5/site-packages/rest_framework/views.py", line 474, in dispatch
    response = handler(request, *args, **kwargs)
  File "/home/jops/university/refactoring/tattoo/vtattoo/vtattooenv/lib/python3.5/site-packages/rest_framework/generics.py", line 240, in get
    return self.list(request, *args, **kwargs)
  File "/home/jops/university/refactoring/tattoo/vtattoo/vtattooenv/lib/python3.5/site-packages/rest_framework/mixins.py", line 40, in list
    queryset = self.filter_queryset(self.get_queryset())
  File "/home/jops/university/refactoring/tattoo/vtattoo/vtattooenv/lib/python3.5/site-packages/rest_framework/generics.py", line 67, in get_queryset
    % self.__class__.__name__
AssertionError: 'DealList' should either include a `queryset` attribute, or override the `get_queryset()` method.
INFO:root:<QuerySet [<Deal: Deal object>, <Deal: Deal object>]>
INFO:root:[(<Tattoo: Tattoo object>, <User: ivdpopovich>, <User: ivdpopovich>), (<Tattoo: Tattoo object>, <User: ivdpopovich>, <User: ivdpopovich>)]
INFO:root:Darova
INFO:root:[(<Tattoo: Tattoo object>, <User: ivdpopovich>), (<Tattoo: Tattoo object>, <User: ivdpopovich>)]
ERROR:django.request:Internal Server Error: /public-deals/
Traceback (most recent call last):
  File "/home/jops/university/refactoring/tattoo/vtattoo/vtattooenv/lib/python3.5/site-packages/django/core/handlers/exception.py", line 41, in inner
    response = get_response(request)
  File "/home/jops/university/refactoring/tattoo/vtattoo/vtattooenv/lib/python3.5/site-packages/django/core/handlers/base.py", line 187, in _get_response
    response = self.process_exception_by_middleware(e, request)
  File "/home/jops/university/refactoring/tattoo/vtattoo/vtattooenv/lib/python3.5/site-packages/django/core/handlers/base.py", line 185, in _get_response
    response = wrapped_callback(request, *callback_args, **callback_kwargs)
  File "/home/jops/university/refactoring/tattoo/vtattoo/vtattooenv/lib/python3.5/site-packages/django/views/decorators/csrf.py", line 58, in wrapped_view
    return view_func(*args, **kwargs)
  File "/home/jops/university/refactoring/tattoo/vtattoo/vtattooenv/lib/python3.5/site-packages/django/views/generic/base.py", line 68, in view
    return self.dispatch(request, *args, **kwargs)
  File "/home/jops/university/refactoring/tattoo/vtattoo/vtattooenv/lib/python3.5/site-packages/rest_framework/views.py", line 477, in dispatch
    response = self.handle_exception(exc)
  File "/home/jops/university/refactoring/tattoo/vtattoo/vtattooenv/lib/python3.5/site-packages/rest_framework/views.py", line 437, in handle_exception
    self.raise_uncaught_exception(exc)
  File "/home/jops/university/refactoring/tattoo/vtattoo/vtattooenv/lib/python3.5/site-packages/rest_framework/views.py", line 448, in raise_uncaught_exception
    raise exc
  File "/home/jops/university/refactoring/tattoo/vtattoo/vtattooenv/lib/python3.5/site-packages/rest_framework/views.py", line 474, in dispatch
    response = handler(request, *args, **kwargs)
  File "/home/jops/university/refactoring/tattoo/vtattoo/vtattooenv/lib/python3.5/site-packages/rest_framework/generics.py", line 243, in post
    return self.create(request, *args, **kwargs)
  File "/home/jops/university/refactoring/tattoo/vtattoo/vtattooenv/lib/python3.5/site-packages/rest_framework/mixins.py", line 20, in create
    serializer.is_valid(raise_exception=True)
  File "/home/jops/university/refactoring/tattoo/vtattoo/vtattooenv/lib/python3.5/site-packages/rest_framework/serializers.py", line 213, in is_valid
    self._validated_data = self.run_validation(self.initial_data)
  File "/home/jops/university/refactoring/tattoo/vtattoo/vtattooenv/lib/python3.5/site-packages/rest_framework/serializers.py", line 404, in run_validation
    value = self.to_internal_value(data)
  File "/home/jops/university/refactoring/tattoo/vtattoo/vtattooenv/lib/python3.5/site-packages/rest_framework/serializers.py", line 428, in to_internal_value
    fields = self._writable_fields
  File "/home/jops/university/refactoring/tattoo/vtattoo/vtattooenv/lib/python3.5/site-packages/django/utils/functional.py", line 35, in __get__
    res = instance.__dict__[self.name] = self.func(instance)
  File "/home/jops/university/refactoring/tattoo/vtattoo/vtattooenv/lib/python3.5/site-packages/rest_framework/serializers.py", line 343, in _writable_fields
    field for field in self.fields.values()
  File "/home/jops/university/refactoring/tattoo/vtattoo/vtattooenv/lib/python3.5/site-packages/rest_framework/serializers.py", line 336, in fields
    for key, value in self.get_fields().items():
  File "/home/jops/university/refactoring/tattoo/vtattoo/vtattooenv/lib/python3.5/site-packages/rest_framework/serializers.py", line 957, in get_fields
    field_names = self.get_field_names(declared_fields, info)
  File "/home/jops/university/refactoring/tattoo/vtattoo/vtattooenv/lib/python3.5/site-packages/rest_framework/serializers.py", line 1054, in get_field_names
    serializer_class=self.__class__.__name__
AssertionError: The field 'user' was declared on serializer DealSerializer, but has not been included in the 'fields' option.
WARNING:django.request:Not Found: /favicon.ico
ERROR:django.request:Internal Server Error: /public-deals/
Traceback (most recent call last):
  File "/home/jops/university/refactoring/tattoo/vtattoo/vtattooenv/lib/python3.5/site-packages/rest_framework/serializers.py", line 879, in create
    instance = ModelClass.objects.create(**validated_data)
  File "/home/jops/university/refactoring/tattoo/vtattoo/vtattooenv/lib/python3.5/site-packages/django/db/models/manager.py", line 85, in manager_method
    return getattr(self.get_queryset(), name)(*args, **kwargs)
  File "/home/jops/university/refactoring/tattoo/vtattoo/vtattooenv/lib/python3.5/site-packages/django/db/models/query.py", line 392, in create
    obj = self.model(**kwargs)
  File "/home/jops/university/refactoring/tattoo/vtattoo/vtattooenv/lib/python3.5/site-packages/django/db/models/base.py", line 571, in __init__
    raise TypeError("'%s' is an invalid keyword argument for this function" % list(kwargs)[0])
TypeError: 'owner' is an invalid keyword argument for this function

During handling of the above exception, another exception occurred:

Traceback (most recent call last):
  File "/home/jops/university/refactoring/tattoo/vtattoo/vtattooenv/lib/python3.5/site-packages/django/core/handlers/exception.py", line 41, in inner
    response = get_response(request)
  File "/home/jops/university/refactoring/tattoo/vtattoo/vtattooenv/lib/python3.5/site-packages/django/core/handlers/base.py", line 187, in _get_response
    response = self.process_exception_by_middleware(e, request)
  File "/home/jops/university/refactoring/tattoo/vtattoo/vtattooenv/lib/python3.5/site-packages/django/core/handlers/base.py", line 185, in _get_response
    response = wrapped_callback(request, *callback_args, **callback_kwargs)
  File "/home/jops/university/refactoring/tattoo/vtattoo/vtattooenv/lib/python3.5/site-packages/django/views/decorators/csrf.py", line 58, in wrapped_view
    return view_func(*args, **kwargs)
  File "/home/jops/university/refactoring/tattoo/vtattoo/vtattooenv/lib/python3.5/site-packages/django/views/generic/base.py", line 68, in view
    return self.dispatch(request, *args, **kwargs)
  File "/home/jops/university/refactoring/tattoo/vtattoo/vtattooenv/lib/python3.5/site-packages/rest_framework/views.py", line 477, in dispatch
    response = self.handle_exception(exc)
  File "/home/jops/university/refactoring/tattoo/vtattoo/vtattooenv/lib/python3.5/site-packages/rest_framework/views.py", line 437, in handle_exception
    self.raise_uncaught_exception(exc)
  File "/home/jops/university/refactoring/tattoo/vtattoo/vtattooenv/lib/python3.5/site-packages/rest_framework/views.py", line 448, in raise_uncaught_exception
    raise exc
  File "/home/jops/university/refactoring/tattoo/vtattoo/vtattooenv/lib/python3.5/site-packages/rest_framework/views.py", line 474, in dispatch
    response = handler(request, *args, **kwargs)
  File "/home/jops/university/refactoring/tattoo/vtattoo/vtattooenv/lib/python3.5/site-packages/rest_framework/generics.py", line 243, in post
    return self.create(request, *args, **kwargs)
  File "/home/jops/university/refactoring/tattoo/vtattoo/vtattooenv/lib/python3.5/site-packages/rest_framework/mixins.py", line 21, in create
    self.perform_create(serializer)
  File "/home/jops/university/refactoring/vtattoo/tattoo/views.py", line 152, in perform_create
    serializer.save(owner=self.request.user)
  File "/home/jops/university/refactoring/tattoo/vtattoo/vtattooenv/lib/python3.5/site-packages/rest_framework/serializers.py", line 191, in save
    self.instance = self.create(validated_data)
  File "/home/jops/university/refactoring/tattoo/vtattoo/vtattooenv/lib/python3.5/site-packages/rest_framework/serializers.py", line 896, in create
    raise TypeError(msg)
TypeError: Got a `TypeError` when calling `Deal.objects.create()`. This may be because you have a writable field on the serializer class that is not a valid argument to `Deal.objects.create()`. You may need to make the field read-only, or override the DealSerializer.create() method to handle this correctly.
Original exception was:
 Traceback (most recent call last):
  File "/home/jops/university/refactoring/tattoo/vtattoo/vtattooenv/lib/python3.5/site-packages/rest_framework/serializers.py", line 879, in create
    instance = ModelClass.objects.create(**validated_data)
  File "/home/jops/university/refactoring/tattoo/vtattoo/vtattooenv/lib/python3.5/site-packages/django/db/models/manager.py", line 85, in manager_method
    return getattr(self.get_queryset(), name)(*args, **kwargs)
  File "/home/jops/university/refactoring/tattoo/vtattoo/vtattooenv/lib/python3.5/site-packages/django/db/models/query.py", line 392, in create
    obj = self.model(**kwargs)
  File "/home/jops/university/refactoring/tattoo/vtattoo/vtattooenv/lib/python3.5/site-packages/django/db/models/base.py", line 571, in __init__
    raise TypeError("'%s' is an invalid keyword argument for this function" % list(kwargs)[0])
TypeError: 'owner' is an invalid keyword argument for this function

ERROR:django.request:Internal Server Error: /public-deals/
Traceback (most recent call last):
  File "/home/jops/university/refactoring/tattoo/vtattoo/vtattooenv/lib/python3.5/site-packages/rest_framework/serializers.py", line 879, in create
    instance = ModelClass.objects.create(**validated_data)
  File "/home/jops/university/refactoring/tattoo/vtattoo/vtattooenv/lib/python3.5/site-packages/django/db/models/manager.py", line 85, in manager_method
    return getattr(self.get_queryset(), name)(*args, **kwargs)
  File "/home/jops/university/refactoring/tattoo/vtattoo/vtattooenv/lib/python3.5/site-packages/django/db/models/query.py", line 392, in create
    obj = self.model(**kwargs)
  File "/home/jops/university/refactoring/tattoo/vtattoo/vtattooenv/lib/python3.5/site-packages/django/db/models/base.py", line 571, in __init__
    raise TypeError("'%s' is an invalid keyword argument for this function" % list(kwargs)[0])
TypeError: 'owner' is an invalid keyword argument for this function

During handling of the above exception, another exception occurred:

Traceback (most recent call last):
  File "/home/jops/university/refactoring/tattoo/vtattoo/vtattooenv/lib/python3.5/site-packages/django/core/handlers/exception.py", line 41, in inner
    response = get_response(request)
  File "/home/jops/university/refactoring/tattoo/vtattoo/vtattooenv/lib/python3.5/site-packages/django/core/handlers/base.py", line 187, in _get_response
    response = self.process_exception_by_middleware(e, request)
  File "/home/jops/university/refactoring/tattoo/vtattoo/vtattooenv/lib/python3.5/site-packages/django/core/handlers/base.py", line 185, in _get_response
    response = wrapped_callback(request, *callback_args, **callback_kwargs)
  File "/home/jops/university/refactoring/tattoo/vtattoo/vtattooenv/lib/python3.5/site-packages/django/views/decorators/csrf.py", line 58, in wrapped_view
    return view_func(*args, **kwargs)
  File "/home/jops/university/refactoring/tattoo/vtattoo/vtattooenv/lib/python3.5/site-packages/django/views/generic/base.py", line 68, in view
    return self.dispatch(request, *args, **kwargs)
  File "/home/jops/university/refactoring/tattoo/vtattoo/vtattooenv/lib/python3.5/site-packages/rest_framework/views.py", line 477, in dispatch
    response = self.handle_exception(exc)
  File "/home/jops/university/refactoring/tattoo/vtattoo/vtattooenv/lib/python3.5/site-packages/rest_framework/views.py", line 437, in handle_exception
    self.raise_uncaught_exception(exc)
  File "/home/jops/university/refactoring/tattoo/vtattoo/vtattooenv/lib/python3.5/site-packages/rest_framework/views.py", line 448, in raise_uncaught_exception
    raise exc
  File "/home/jops/university/refactoring/tattoo/vtattoo/vtattooenv/lib/python3.5/site-packages/rest_framework/views.py", line 474, in dispatch
    response = handler(request, *args, **kwargs)
  File "/home/jops/university/refactoring/tattoo/vtattoo/vtattooenv/lib/python3.5/site-packages/rest_framework/generics.py", line 243, in post
    return self.create(request, *args, **kwargs)
  File "/home/jops/university/refactoring/tattoo/vtattoo/vtattooenv/lib/python3.5/site-packages/rest_framework/mixins.py", line 21, in create
    self.perform_create(serializer)
  File "/home/jops/university/refactoring/vtattoo/tattoo/views.py", line 152, in perform_create
    serializer.save(owner=self.request.user)
  File "/home/jops/university/refactoring/tattoo/vtattoo/vtattooenv/lib/python3.5/site-packages/rest_framework/serializers.py", line 191, in save
    self.instance = self.create(validated_data)
  File "/home/jops/university/refactoring/tattoo/vtattoo/vtattooenv/lib/python3.5/site-packages/rest_framework/serializers.py", line 896, in create
    raise TypeError(msg)
TypeError: Got a `TypeError` when calling `Deal.objects.create()`. This may be because you have a writable field on the serializer class that is not a valid argument to `Deal.objects.create()`. You may need to make the field read-only, or override the DealSerializer.create() method to handle this correctly.
Original exception was:
 Traceback (most recent call last):
  File "/home/jops/university/refactoring/tattoo/vtattoo/vtattooenv/lib/python3.5/site-packages/rest_framework/serializers.py", line 879, in create
    instance = ModelClass.objects.create(**validated_data)
  File "/home/jops/university/refactoring/tattoo/vtattoo/vtattooenv/lib/python3.5/site-packages/django/db/models/manager.py", line 85, in manager_method
    return getattr(self.get_queryset(), name)(*args, **kwargs)
  File "/home/jops/university/refactoring/tattoo/vtattoo/vtattooenv/lib/python3.5/site-packages/django/db/models/query.py", line 392, in create
    obj = self.model(**kwargs)
  File "/home/jops/university/refactoring/tattoo/vtattoo/vtattooenv/lib/python3.5/site-packages/django/db/models/base.py", line 571, in __init__
    raise TypeError("'%s' is an invalid keyword argument for this function" % list(kwargs)[0])
TypeError: 'owner' is an invalid keyword argument for this function

ERROR:django.request:Internal Server Error: /deals/
Traceback (most recent call last):
  File "/home/jops/university/refactoring/tattoo/vtattoo/vtattooenv/lib/python3.5/site-packages/django/core/handlers/exception.py", line 41, in inner
    response = get_response(request)
  File "/home/jops/university/refactoring/tattoo/vtattoo/vtattooenv/lib/python3.5/site-packages/django/core/handlers/base.py", line 187, in _get_response
    response = self.process_exception_by_middleware(e, request)
  File "/home/jops/university/refactoring/tattoo/vtattoo/vtattooenv/lib/python3.5/site-packages/django/core/handlers/base.py", line 185, in _get_response
    response = wrapped_callback(request, *callback_args, **callback_kwargs)
  File "/home/jops/university/refactoring/tattoo/vtattoo/vtattooenv/lib/python3.5/site-packages/django/views/decorators/csrf.py", line 58, in wrapped_view
    return view_func(*args, **kwargs)
  File "/home/jops/university/refactoring/tattoo/vtattoo/vtattooenv/lib/python3.5/site-packages/django/views/generic/base.py", line 68, in view
    return self.dispatch(request, *args, **kwargs)
  File "/home/jops/university/refactoring/tattoo/vtattoo/vtattooenv/lib/python3.5/site-packages/rest_framework/views.py", line 477, in dispatch
    response = self.handle_exception(exc)
  File "/home/jops/university/refactoring/tattoo/vtattoo/vtattooenv/lib/python3.5/site-packages/rest_framework/views.py", line 437, in handle_exception
    self.raise_uncaught_exception(exc)
  File "/home/jops/university/refactoring/tattoo/vtattoo/vtattooenv/lib/python3.5/site-packages/rest_framework/views.py", line 448, in raise_uncaught_exception
    raise exc
  File "/home/jops/university/refactoring/tattoo/vtattoo/vtattooenv/lib/python3.5/site-packages/rest_framework/views.py", line 474, in dispatch
    response = handler(request, *args, **kwargs)
  File "/home/jops/university/refactoring/tattoo/vtattoo/vtattooenv/lib/python3.5/site-packages/rest_framework/generics.py", line 240, in get
    return self.list(request, *args, **kwargs)
  File "/home/jops/university/refactoring/tattoo/vtattoo/vtattooenv/lib/python3.5/site-packages/rest_framework/mixins.py", line 40, in list
    queryset = self.filter_queryset(self.get_queryset())
  File "/home/jops/university/refactoring/vtattoo/tattoo/views.py", line 162, in get_queryset
    deal.img = deal.tattoo.img_file
AttributeError: 'Tattoo' object has no attribute 'img_file'
ERROR:django.request:Internal Server Error: /deals/
Traceback (most recent call last):
  File "/home/jops/university/refactoring/tattoo/vtattoo/vtattooenv/lib/python3.5/site-packages/django/core/handlers/exception.py", line 41, in inner
    response = get_response(request)
  File "/home/jops/university/refactoring/tattoo/vtattoo/vtattooenv/lib/python3.5/site-packages/django/core/handlers/base.py", line 187, in _get_response
    response = self.process_exception_by_middleware(e, request)
  File "/home/jops/university/refactoring/tattoo/vtattoo/vtattooenv/lib/python3.5/site-packages/django/core/handlers/base.py", line 185, in _get_response
    response = wrapped_callback(request, *callback_args, **callback_kwargs)
  File "/home/jops/university/refactoring/tattoo/vtattoo/vtattooenv/lib/python3.5/site-packages/django/views/decorators/csrf.py", line 58, in wrapped_view
    return view_func(*args, **kwargs)
  File "/home/jops/university/refactoring/tattoo/vtattoo/vtattooenv/lib/python3.5/site-packages/django/views/generic/base.py", line 68, in view
    return self.dispatch(request, *args, **kwargs)
  File "/home/jops/university/refactoring/tattoo/vtattoo/vtattooenv/lib/python3.5/site-packages/rest_framework/views.py", line 477, in dispatch
    response = self.handle_exception(exc)
  File "/home/jops/university/refactoring/tattoo/vtattoo/vtattooenv/lib/python3.5/site-packages/rest_framework/views.py", line 437, in handle_exception
    self.raise_uncaught_exception(exc)
  File "/home/jops/university/refactoring/tattoo/vtattoo/vtattooenv/lib/python3.5/site-packages/rest_framework/views.py", line 448, in raise_uncaught_exception
    raise exc
  File "/home/jops/university/refactoring/tattoo/vtattoo/vtattooenv/lib/python3.5/site-packages/rest_framework/views.py", line 474, in dispatch
    response = handler(request, *args, **kwargs)
  File "/home/jops/university/refactoring/tattoo/vtattoo/vtattooenv/lib/python3.5/site-packages/rest_framework/generics.py", line 240, in get
    return self.list(request, *args, **kwargs)
  File "/home/jops/university/refactoring/tattoo/vtattoo/vtattooenv/lib/python3.5/site-packages/rest_framework/mixins.py", line 45, in list
    return self.get_paginated_response(serializer.data)
  File "/home/jops/university/refactoring/tattoo/vtattoo/vtattooenv/lib/python3.5/site-packages/rest_framework/serializers.py", line 702, in data
    ret = super(ListSerializer, self).data
  File "/home/jops/university/refactoring/tattoo/vtattoo/vtattooenv/lib/python3.5/site-packages/rest_framework/serializers.py", line 239, in data
    self._data = self.to_representation(self.instance)
  File "/home/jops/university/refactoring/tattoo/vtattoo/vtattooenv/lib/python3.5/site-packages/rest_framework/serializers.py", line 620, in to_representation
    self.child.to_representation(item) for item in iterable
  File "/home/jops/university/refactoring/tattoo/vtattoo/vtattooenv/lib/python3.5/site-packages/rest_framework/serializers.py", line 620, in <listcomp>
    self.child.to_representation(item) for item in iterable
  File "/home/jops/university/refactoring/tattoo/vtattoo/vtattooenv/lib/python3.5/site-packages/rest_framework/serializers.py", line 456, in to_representation
    fields = self._readable_fields
  File "/home/jops/university/refactoring/tattoo/vtattoo/vtattooenv/lib/python3.5/site-packages/django/utils/functional.py", line 35, in __get__
    res = instance.__dict__[self.name] = self.func(instance)
  File "/home/jops/university/refactoring/tattoo/vtattoo/vtattooenv/lib/python3.5/site-packages/rest_framework/serializers.py", line 350, in _readable_fields
    field for field in self.fields.values()
  File "/home/jops/university/refactoring/tattoo/vtattoo/vtattooenv/lib/python3.5/site-packages/rest_framework/serializers.py", line 336, in fields
    for key, value in self.get_fields().items():
  File "/home/jops/university/refactoring/tattoo/vtattoo/vtattooenv/lib/python3.5/site-packages/rest_framework/serializers.py", line 957, in get_fields
    field_names = self.get_field_names(declared_fields, info)
  File "/home/jops/university/refactoring/tattoo/vtattoo/vtattooenv/lib/python3.5/site-packages/rest_framework/serializers.py", line 1054, in get_field_names
    serializer_class=self.__class__.__name__
AssertionError: The field 'image' was declared on serializer DealSerializer, but has not been included in the 'fields' option.
ERROR:django.request:Internal Server Error: /deals/
Traceback (most recent call last):
  File "/home/jops/university/refactoring/tattoo/vtattoo/vtattooenv/lib/python3.5/site-packages/django/core/handlers/exception.py", line 41, in inner
    response = get_response(request)
  File "/home/jops/university/refactoring/tattoo/vtattoo/vtattooenv/lib/python3.5/site-packages/django/core/handlers/base.py", line 217, in _get_response
    response = self.process_exception_by_middleware(e, request)
  File "/home/jops/university/refactoring/tattoo/vtattoo/vtattooenv/lib/python3.5/site-packages/django/core/handlers/base.py", line 215, in _get_response
    response = response.render()
  File "/home/jops/university/refactoring/tattoo/vtattoo/vtattooenv/lib/python3.5/site-packages/django/template/response.py", line 107, in render
    self.content = self.rendered_content
  File "/home/jops/university/refactoring/tattoo/vtattoo/vtattooenv/lib/python3.5/site-packages/rest_framework/response.py", line 72, in rendered_content
    ret = renderer.render(self.data, accepted_media_type, context)
  File "/home/jops/university/refactoring/tattoo/vtattoo/vtattooenv/lib/python3.5/site-packages/rest_framework/renderers.py", line 103, in render
    separators=separators
  File "/usr/lib/python3.5/json/__init__.py", line 237, in dumps
    **kw).encode(obj)
  File "/usr/lib/python3.5/json/encoder.py", line 198, in encode
    chunks = self.iterencode(o, _one_shot=True)
  File "/usr/lib/python3.5/json/encoder.py", line 256, in iterencode
    return _iterencode(o, 0)
  File "/home/jops/university/refactoring/tattoo/vtattoo/vtattooenv/lib/python3.5/site-packages/rest_framework/utils/encoders.py", line 54, in default
    return obj.decode('utf-8')
UnicodeDecodeError: 'utf-8' codec can't decode byte 0xff in position 0: invalid start byte
ERROR:django.request:Internal Server Error: /deals/
Traceback (most recent call last):
  File "/home/jops/university/refactoring/tattoo/vtattoo/vtattooenv/lib/python3.5/site-packages/django/core/handlers/exception.py", line 41, in inner
    response = get_response(request)
  File "/home/jops/university/refactoring/tattoo/vtattoo/vtattooenv/lib/python3.5/site-packages/django/core/handlers/base.py", line 217, in _get_response
    response = self.process_exception_by_middleware(e, request)
  File "/home/jops/university/refactoring/tattoo/vtattoo/vtattooenv/lib/python3.5/site-packages/django/core/handlers/base.py", line 215, in _get_response
    response = response.render()
  File "/home/jops/university/refactoring/tattoo/vtattoo/vtattooenv/lib/python3.5/site-packages/django/template/response.py", line 107, in render
    self.content = self.rendered_content
  File "/home/jops/university/refactoring/tattoo/vtattoo/vtattooenv/lib/python3.5/site-packages/rest_framework/response.py", line 72, in rendered_content
    ret = renderer.render(self.data, accepted_media_type, context)
  File "/home/jops/university/refactoring/tattoo/vtattoo/vtattooenv/lib/python3.5/site-packages/rest_framework/renderers.py", line 103, in render
    separators=separators
  File "/usr/lib/python3.5/json/__init__.py", line 237, in dumps
    **kw).encode(obj)
  File "/usr/lib/python3.5/json/encoder.py", line 198, in encode
    chunks = self.iterencode(o, _one_shot=True)
  File "/usr/lib/python3.5/json/encoder.py", line 256, in iterencode
    return _iterencode(o, 0)
  File "/home/jops/university/refactoring/tattoo/vtattoo/vtattooenv/lib/python3.5/site-packages/rest_framework/utils/encoders.py", line 54, in default
    return obj.decode('utf-8')
UnicodeDecodeError: 'utf-8' codec can't decode byte 0xff in position 0: invalid start byte
INFO:root:<QuerySet [<Tattoo: Tattoo object>, <Tattoo: Tattoo object>, <Tattoo: Tattoo object>, <Tattoo: Tattoo object>, <Tattoo: Tattoo object>, <Tattoo: Tattoo object>, <Tattoo: Tattoo object>]>
INFO:root:[('index_1', <User: ivdpopovich>), ('index_2', <User: ivdpopovich>), ('index_3', <User: ivdpopovich>), ('index_4', <User: ivdpopovich>), ('index_5', <User: ivdpopovich>), ('index_6', <User: ivdpopovich>), ('viewside', <User: emily>)]
INFO:root:<QuerySet [<Tattoo: Tattoo object>, <Tattoo: Tattoo object>, <Tattoo: Tattoo object>, <Tattoo: Tattoo object>, <Tattoo: Tattoo object>, <Tattoo: Tattoo object>, <Tattoo: Tattoo object>]>
INFO:root:[('index_1', <User: ivdpopovich>), ('index_2', <User: ivdpopovich>), ('index_3', <User: ivdpopovich>), ('index_4', <User: ivdpopovich>), ('index_5', <User: ivdpopovich>), ('index_6', <User: ivdpopovich>), ('viewside', <User: emily>)]
INFO:root:<QuerySet [<Tattoo: Tattoo object>, <Tattoo: Tattoo object>, <Tattoo: Tattoo object>, <Tattoo: Tattoo object>, <Tattoo: Tattoo object>, <Tattoo: Tattoo object>, <Tattoo: Tattoo object>]>
INFO:root:[('index_1', <User: ivdpopovich>), ('index_2', <User: ivdpopovich>), ('index_3', <User: ivdpopovich>), ('index_4', <User: ivdpopovich>), ('index_5', <User: ivdpopovich>), ('index_6', <User: ivdpopovich>), ('viewside', <User: emily>)]
INFO:root:<QuerySet [<Tattoo: Tattoo object>, <Tattoo: Tattoo object>, <Tattoo: Tattoo object>, <Tattoo: Tattoo object>, <Tattoo: Tattoo object>, <Tattoo: Tattoo object>, <Tattoo: Tattoo object>]>
INFO:root:[('index_1', <User: ivdpopovich>), ('index_2', <User: ivdpopovich>), ('index_3', <User: ivdpopovich>), ('index_4', <User: ivdpopovich>), ('index_5', <User: ivdpopovich>), ('index_6', <User: ivdpopovich>), ('viewside', <User: emily>)]
INFO:root:<QuerySet [<Tattoo: Tattoo object>, <Tattoo: Tattoo object>, <Tattoo: Tattoo object>, <Tattoo: Tattoo object>, <Tattoo: Tattoo object>, <Tattoo: Tattoo object>, <Tattoo: Tattoo object>]>
INFO:root:[('index_1', <User: ivdpopovich>), ('index_2', <User: ivdpopovich>), ('index_3', <User: ivdpopovich>), ('index_4', <User: ivdpopovich>), ('index_5', <User: ivdpopovich>), ('index_6', <User: ivdpopovich>), ('viewside', <User: emily>)]
WARNING:django.request:Not Found: /public-deals/
WARNING:django.request:Not Found: /public-deals/
